Workbook

Sheet Tổng hợp
A1: HỒ SƠ QUẢN LÝ DỰ ÁN
A2: Được cập nhật theo tài liệu UEBA hiện có — nguồn tin cậy duy nhất về tình hình dự án
A3: Tình hình hiện tại | B3: Đã qua 2 tuần đầu; W3 đang khởi động MVP nền
A5: Tên dự án | B5: Vespionage / UEBA Endpoint Monitoring
A6: Nhóm | B6: 47
A7: Ngày bắt đầu | B7: 30/05/2026
A8: Ngày kết thúc dự kiến | B8: 06/07/2026
A9: Trưởng nhóm / Điều phối | B9: Hoàng Trung Quân
A10: Mentor phụ trách | B10: Quốc
A11: Đối tác sử dụng (Stakeholder) | B11: Security Admin, SOC/Security Analyst, SysAdmin, Risk & Compliance
A12: Kho lưu mã nguồn (GitHub) | B12: https://github.com/AI20K-Build-Cohort-2/C2-App-047
A13: Địa chỉ sản phẩm (Live URL) | B13: [Dán link sản phẩm đã triển khai trong W5-W6]
A14: Mục tiêu dự án | B14: Xây dựng web/app UEBA phát hiện hành vi bất thường từ log CERT r4.2/agent, chấm điểm rủi ro, tạo alert, giải thích bằng LLM/fallback và deploy online.
A16: TỔNG HỢP TIẾN ĐỘ THEO SPRINT
A18: Sprint | B18: Giai đoạn | C18: Từ ngày | D18: Đến ngày | E18: Tổng số việc | F18: Đã xong | G18: Đang làm | H18: Trạng thái
A19: Sprint 1 | B19: Nền tảng sản phẩm | C19: 30/05/2026 | D19: 05/06/2026 | E19: =COUNTIF(Backlog!$F:$F,A19) -> 3 | F19: =COUNTIFS(Backlog!$F:$F,A19,Backlog!$K:$K,"Hoàn thành") -> 3 | G19: =COUNTIFS(Backlog!$F:$F,A19,Backlog!$K:$K,"Đang làm") -> 0 | H19: Hoàn thành
A20: Sprint 2 | B20: Data/API/ML scaffold | C20: 06/06/2026 | D20: 12/06/2026 | E20: =COUNTIF(Backlog!$F:$F,A20) -> 3 | F20: =COUNTIFS(Backlog!$F:$F,A20,Backlog!$K:$K,"Hoàn thành") -> 3 | G20: =COUNTIFS(Backlog!$F:$F,A20,Backlog!$K:$K,"Đang làm") -> 0 | H20: Hoàn thành
A21: Sprint 3 | B21: MVP nền chạy được | C21: 13/06/2026 | D21: 19/06/2026 | E21: =COUNTIF(Backlog!$F:$F,A21) -> 6 | F21: =COUNTIFS(Backlog!$F:$F,A21,Backlog!$K:$K,"Hoàn thành") -> 0 | G21: =COUNTIFS(Backlog!$F:$F,A21,Backlog!$K:$K,"Đang làm") -> 6 | H21: Đang làm
A22: Sprint 4 | B22: Anomaly engine + alert loop | C22: 20/06/2026 | D22: 26/06/2026 | E22: =COUNTIF(Backlog!$F:$F,A22) -> 6 | F22: =COUNTIFS(Backlog!$F:$F,A22,Backlog!$K:$K,"Hoàn thành") -> 0 | G22: =COUNTIFS(Backlog!$F:$F,A22,Backlog!$K:$K,"Đang làm") -> 0 | H22: Chưa bắt đầu
A23: Sprint 5 | B23: E2E + QA + deploy staging | C23: 27/06/2026 | D23: 03/07/2026 | E23: =COUNTIF(Backlog!$F:$F,A23) -> 5 | F23: =COUNTIFS(Backlog!$F:$F,A23,Backlog!$K:$K,"Hoàn thành") -> 0 | G23: =COUNTIFS(Backlog!$F:$F,A23,Backlog!$K:$K,"Đang làm") -> 0 | H23: Chưa bắt đầu
A24: Sprint 6 | B24: Final deploy + bàn giao | C24: 46119 | D24: 46180 | E24: =COUNTIF(Backlog!$F:$F,A24) -> 4 | F24: =COUNTIFS(Backlog!$F:$F,A24,Backlog!$K:$K,"Hoàn thành") -> 0 | G24: =COUNTIFS(Backlog!$F:$F,A24,Backlog!$K:$K,"Đang làm") -> 0 | H24: Chưa bắt đầu
A26: CHỈ SỐ THEO DÕI CHÍNH
A28: Tổng số User Story | B28: =COUNTA('Danh sách User Story'!A5:A20) -> 16 | C28: câu
A29: Tính năng đã hoàn thành | B29: =COUNTIF('Danh sách User Story'!H5:H20,"Hoàn thành")&" / "&COUNTA('Danh sách User Story'!A5:A20) -> 4 / 16
A30: Lỗi đang mở | B30: =COUNTIF('Theo dõi lỗi'!K5:K35,"Mở") -> 6 | C30: Nghiêm trọng / Cao / Trung bình / Thấp
A31: Số lần gặp đối tác | C31: lần
A32: Mức hài lòng (Demo) | C32: trên 10
A33: Tình trạng triển khai | B33: Local → Staging W5 → Production demo W6

Sheet Đường link quan trọng
A1: ĐƯỜNG LINK QUAN TRỌNG
A2: Liên kết cần cập nhật trong quá trình triển khai UEBA
A4: STT | B4: Phân loại | C4: Nội dung / Mô tả | D4: Địa chỉ (URL) | E4: Người quản lý | F4: Ghi chú
B5: Mã nguồn và Triển khai
A6: 1 | C6: GitHub repo | D6: https://github.com/AI20K-Build-Cohort-2/C2-App-047 | E6: Bùi Hoàng Linh | F6: Code source chính
A7: 2 | C7: Backend API URL | D7: [Điền Render/Railway/Fly.io URL trong W5-W6] | E7: Bùi Hoàng Linh | F7: Không để localhost-only
A8: 3 | C8: Frontend dashboard URL | D8: [Điền Vercel/Netlify URL trong W5-W6] | E8: Hoàng Trung Quân | F8: URL demo public
A9: 4 | C9: API docs / Swagger | D9: [Điền /docs của backend khi deploy] | E9: Bùi Hoàng Linh | F9: Dùng để mentor kiểm tra API
A10: 5 | C10: Demo script / walkthrough | D10: presentation/demo_script.md | E10: Hoàng Trung Quân | F10: Luồng demo cuối kỳ
A11: 6 | C11: Model report | D11: eval/results/model_report.md | E11: Mai Ngọc Duy | F11: Metrics và known scenario detection
B12: Liên lạc và Hợp tác
A13: 7 | C13: Kênh Discord nhóm
B14: Đối tác (Stakeholder)
A15: 8 | C15: Biên bản họp với đối tác | D15: [Dán link vào đây] | E15: [Họ tên] | F15: Google Doc, Notion, v.v.
A16: 9 | C16: Báo cáo phản hồi từ đối tác | D16: [Dán link vào đây] | E16: [Họ tên]

Sheet Thành viên nhóm
A1: DANH SÁCH THÀNH VIÊN NHÓM
A2: Phân vai theo dự án AI20K-107 UEBA
A4: STT | B4: Họ và tên | C4: Vai trò chính | D4: Vai trò phụ | E4: Email | F4: Discord | G4: GitHub | H4: Cam kết (giờ/tuần) | I4: Ghi chú
A5: 1 | B5: Mai Ngọc Duy | C5: Data/ML Engineer | D5: CERT import, feature engineering, iForest, metrics | H5: 40 | I5: Owner pipeline ML và đánh giá model
A6: 2 | B6: Bùi Hoàng Linh | C6: Backend/DevOps Engineer | D6: FastAPI, DB schema, auth/RBAC, deploy backend | H6: 40 | I6: Owner API, database, integration và CI/Docker
A7: 3 | B7: Hoàng Trung Quân | C7: Frontend/LLM/Product | D7: Dashboard, LLM explanation, UX, demo docs | H7: 40 | I7: Owner UI, analyst workflow, README/demo
A9: BẢNG PHÂN VAI THEO WORKSTREAM
A10: Data contract & CERT r4.2 | B10: Mai Ngọc Duy + Bùi Hoàng Linh | C10: Chuẩn hóa logon/device/file/http/email/LDAP/psychometric; build user-day feature matrix | D10: Normalized events + artifacts/preprocessing/*.csv
A11: ML anomaly + risk scoring | B11: Mai Ngọc Duy + Hoàng Trung Quân | C11: Train Isolation Forest, batch inference, score 0-100, top anomalous features | D11: Model artifact + metrics + alert candidates
A12: Backend API & database | B12: Bùi Hoàng Linh + Mai Ngọc Duy | C12: Auth/JWT/RBAC, users/devices/logs/alerts/dashboard/model endpoints | D12: FastAPI service + persistent DB
A13: Frontend dashboard | B13: Hoàng Trung Quân + Bùi Hoàng Linh | C13: Login, overview, users/devices/logs/alerts, alert detail, timeline | D13: Web app deployable with complete UI/UX
A14: LLM explanation/fallback | B14: Hoàng Trung Quân + Mai Ngọc Duy | C14: Prompt/template explanation từ anomaly context, risk factors, timeline | D14: Explanation service with rule-based fallback
A15: QA, docs, deployment | B15: Bùi Hoàng Linh + Hoàng Trung Quân | C15: Test API/E2E, Docker, deploy URL, README, demo script | D15: Public URL + final demo package

Sheet Danh sách User Story
A1: DANH SÁCH USER STORY / USE CASE
A2: UEBA Endpoint Monitoring
A4: Mã | B4: Tên câu chuyện sử dụng | C4: Mô tả ngắn | D4: Với vai trò | E4: Tôi muốn | F4: Để đạt được | G4: Mức ưu tiên | H4: Trạng thái | I4: Sprint dự kiến | J4: Xem đặc tả
A5: US-01 | B5: Đăng nhập dashboard bằng JWT | C5: Login email/password, token dùng gọi API quản trị | D5: Admin/Analyst | E5: đăng nhập an toàn | F5: chỉ người có quyền truy cập dashboard | G5: Bắt buộc | H5: Hoàn thành | I5: Sprint 1 | J5: Spec Auth
A6: US-02 | B6: Phân quyền admin/analyst | C6: Giới hạn chức năng nhạy cảm theo role | D6: Admin | E6: phân biệt quyền admin và analyst | F6: đảm bảo kiểm soát truy cập cơ bản | G6: Bắt buộc | H6: Hoàn thành | I6: Sprint 1 | J6: Spec Auth
A7: US-03 | B7: Chuẩn hóa endpoint events | C7: Map CERT CSV sang schema normalized endpoint event | D7: Data/ML Engineer | E7: chuẩn hóa log | F7: dashboard và model dùng cùng contract | G7: Bắt buộc | H7: Hoàn thành | I7: Sprint 2 | J7: Spec Data/ML
A8: US-04 | B8: Import CERT r4.2 | C8: Import logon/device/file/http/email/LDAP/psychometric | D8: Data/ML Engineer | E8: import dataset thật | F8: có nguồn log chính cho training/demo | G8: Bắt buộc | H8: Hoàn thành | I8: Sprint 2 | J8: Spec Data/ML
A9: US-05 | B9: Xem danh sách và chi tiết user | C9: Danh sách user, filter department/role/status, risk score | D9: Admin | E9: theo dõi từng nhân viên/tài khoản | F9: ưu tiên user có risk cao | G9: Bắt buộc | H9: Đang làm | I9: Sprint 3 | J9: Spec Dashboard
A10: US-06 | B10: Quản lý user demo | C10: Thêm/sửa/khóa user demo và thông tin phòng ban/vai trò | D10: Admin | E10: quản lý user demo | F10: mô phỏng dữ liệu nhân sự | G10: Nên có | H10: Đang làm | I10: Sprint 3 | J10: Spec Backend
A11: US-07 | B11: Xem danh sách thiết bị | C11: Device list, assigned user, status, last_seen, risk | D11: Admin | E11: theo dõi thiết bị công ty cấp | F11: biết thiết bị nào có rủi ro | G11: Bắt buộc | H11: Đang làm | I11: Sprint 3 | J11: Spec Dashboard
A12: US-08 | B12: Gán device cho user | C12: Quản lý owner thiết bị tại một thời điểm | D12: Admin | E12: gán device cho user | F12: phân tích hành vi đúng ngữ cảnh | G12: Nên có | H12: Đang làm | I12: Sprint 3 | J12: Spec Backend
A13: US-09 | B13: Lưu normalized logs và API ingest | C13: Lưu event có source_id/source_file và POST /api/logs/ingest | D13: Hệ thống | E13: lưu log truy vết được | F13: phục vụ timeline và phase agent thật | G13: Bắt buộc | H13: Đang làm | I13: Sprint 3 | J13: Spec Backend
A14: US-10 | B14: Train ML anomaly detection | C14: Feature windows, Isolation Forest, artifact, metrics | D14: Data/ML Engineer | E14: train model | F14: phát hiện bất thường dựa trên baseline | G14: Bắt buộc | H14: Chưa bắt đầu | I14: Sprint 4 | J14: Spec Data/ML
A15: US-11 | B15: Risk score 0-100 | C15: Chuyển anomaly score + feature severity sang Low/Medium/High/Critical | D15: Analyst | E15: xem risk score chuẩn hóa | F15: ưu tiên xử lý cảnh báo | G15: Bắt buộc | H15: Chưa bắt đầu | I15: Sprint 4 | J15: Spec ML/API
... A22: US-18 | B22: README, demo script và bàn giao | C22: Tài khoản demo, hướng dẫn chạy/import/train/infer/deploy, privacy note | D22: Team/Stakeholder | E22: có tài liệu bàn giao | F22: demo cuối kỳ mạch lạc và kiểm chứng được | G22: Bắt buộc | H22: Chưa bắt đầu | I22: Sprint 6 | J22: Spec README/Demo
A24: THANG MỨC ƯU TIÊN
A25: Bắt buộc | B25: Sản phẩm không hoạt động nếu thiếu — Phải hoàn thành
A26: Nên có | B26: Tăng giá trị đáng kể nhưng không ảnh hưởng lõi demo
A27: Có thì tốt | B27: Làm nếu còn thời gian — Không ảnh hưởng nếu bỏ qua
A28: Không làm | B28: Ngoài phạm vi giai đoạn MVP

Sheet Lộ trình
A1: LỘ TRÌNH DỰ ÁN — CÁC MỐC CHÍNH
A2: Tập trung MVP web/app có deploy URL
A4: Mã | B4: Mốc quan trọng | C4: Mô tả chi tiết | D4: Tuần | E4: Từ ngày | F4: Đến ngày | G4: Người chịu trách nhiệm | H4: Trạng thái | I4: Kết quả giao nộp
A5: M1 | B5: Chốt brief/PRD/requirements | C5: Why/Who, scope MVP, demo flow, user stories, privacy note | D5: W1 | E5: 30/05/2026 | F5: 46148 | G5: Hoàng Trung Quân | H5: Hoàn thành | I5: BRIEF.md, PRD.md, UEBA_REQUIREMENTS.md
A6: M2 | B6: Chốt architecture/repo/data contract | C6: FastAPI scaffold, repo standard, normalized event schema, CERT mapping | D6: W2 | E6: 06/06/2026 | F6: 46362 | G6: Bùi Hoàng Linh | H6: Hoàn thành | I6: ARCHITECTURE.md, DATA_CONTRACT.md, repo structure
A7: M3 | B7: MVP nền: auth + DB + import + UI shell | C7: Login/RBAC, schema users/devices/logs/alerts, import CERT subset, feature matrix, dashboard shell | D7: W3 | E7: 13/06/2026 | F7: 19/06/2026 | G7: Duy + Linh + Quân | H7: Đang làm | I7: API chạy được + UI shell + data import demo
A8: M4 | B8: Anomaly engine + alert loop | C8: Train iForest, inference, risk 0-100, tạo alert risk>=60, alert APIs | D8: W4 | E8: 20/06/2026 | F8: 26/06/2026 | G8: Duy + Linh | H8: Chưa bắt đầu | I8: Model artifact + risk scoring + alert generation
A9: M5 | B9: Analyst workflow hoàn chỉnh | C9: Alert list/detail, timeline, LLM/fallback explanation, charts overview, status update | D9: W5 | E9: 27/06/2026 | F9: 03/07/2026 | G9: Quân + Linh + Duy | H9: Chưa bắt đầu | I9: Luồng demo end-to-end từ import → alert → explanation
A10: M6 | B10: QA + Deploy + Demo final | C10: Test, Docker, deploy online, README, privacy note, demo script, final presentation | D10: W6 | E10: 04/07/2026 | F10: 06/07/2026 | G10: Quân + Linh + Duy | H10: Chưa bắt đầu | I10: Public URL + README + kịch bản demo + báo cáo

Sheet Backlog
A1: BACKLOG — QUẢN LÝ CÔNG VIỆC THEO SPRINT
A2: AI20K-107 UEBA: hoàn thiện MVP web/app, anomaly detection, LLM explanation và deploy URL
A4: STT | B4: Mã việc | C4: Tên công việc | D4: Mã US liên quan | E4: Mô tả chi tiết | F4: Sprint | G4: Ưu tiên | H4: Dự kiến (giờ) | I4: Người phụ trách | J4: Hạn chót | K4: Trạng thái | L4: Link Spec / PR | M4: Vướng mắc | N4: Ghi chú
B5: Sprint 1: W1 — Hoàn thành nền tảng sản phẩm
A6: 1 | B6: T-001 | C6: Chốt Product Brief / Why-Who | D6: US-01 | E6: Xác định bài toán UEBA, persona, scope, privacy, tiêu chí MVP | F6: Sprint 1 | G6: P0 | H6: 4 | I6: Hoàng Trung Quân | J6: 05/06/2026 | K6: Hoàn thành | L6: docs/BRIEF.md | N6: Nền tảng định hướng sản phẩm
A7: 2 | B7: T-002 | C7: Viết PRD và yêu cầu triển khai | D7: US-01, US-15 | E7: Mô tả MVP loop, user stories, acceptance criteria, demo flow | F7: Sprint 1 | G7: P0 | H7: 8 | I7: Hoàng Trung Quân | J7: 05/06/2026 | K7: Hoàn thành | L7: docs/PRD.md | N7: Dùng làm source of truth
A8: 3 | B8: T-003 | C8: Thiết kế architecture + repo standard | D8: US-09 | E8: Chốt module boundaries src/api, src/models, src/services, src/agents | F8: Sprint 1 | G8: P0 | H8: 6 | I8: Bùi Hoàng Linh | J8: 05/06/2026 | K8: Hoàn thành | L8: docs/ARCHITECTURE.md | N8: Bám starter-code-template
B9: Sprint 2: W2 — Chuẩn bị data/API/ML scaffold
A10: 4 | B10: T-004 | C10: Chốt Data Contract CERT r4.2 | D10: US-07, US-08 | E10: Normalized endpoint event, mapping logon/device/file/http/email/LDAP, feature outputs | F10: Sprint 2 | G10: P0 | H10: 6 | I10: Mai Ngọc Duy | J10: 12/06/2026 | K10: Hoàn thành | L10: docs/DATA_CONTRACT.md | N10: Dữ liệu làm cầu nối backend-ML
A11: 5 | B11: T-005 | C11: FastAPI scaffold và route nền | D11: US-09 | E11: Healthcheck, routes.py, schema Pydantic nền, cấu trúc services | F11: Sprint 2 | G11: P0 | H11: 8 | I11: Bùi Hoàng Linh | J11: 12/06/2026 | K11: Hoàn thành | L11: src/main.py, src/api/routes.py | N11: Cần tiếp tục mở rộng DB/auth
A12: 6 | B12: T-006 | C12: ML preprocessing/iForest scaffold | D12: US-11 | E12: Pipeline tạo user_day_features, feature matrix, feature columns | F12: Sprint 2 | G12: P0 | H12: 10 | I12: Mai Ngọc Duy | J12: 12/06/2026 | K12: Hoàn thành | L12: src/services/ueba_ml/pipelines | N12: Đã có artifacts local cho demo
B13: Sprint 3: W3 — dựng MVP nền chạy được
A14: 7 | B14: T-007 | C14: Thiết kế DB schema + migration/seed | D14: US-03, US-05, US-09, US-13 | E14: Bảng app_accounts, users, devices, event_logs, feature_windows, model_artifacts, alerts; seed admin/analyst | F14: Sprint 3 | G14: P0 | H14: 10 | I14: Bùi Hoàng Linh | J14: 16/06/2026 | K14: Đang làm | L14: src/models/schemas.py | N14: Ưu tiên để frontend tích hợp sớm
A15: 8 | B15: T-008 | C15: Auth JWT + RBAC middleware | D15: US-01, US-02 | E15: Login admin@demo.com/analyst@demo.com, /me, role check admin/analyst | F15: Sprint 3 | G15: P0 | H15: 8 | I15: Bùi Hoàng Linh | J15: 17/06/2026 | K15: Đang làm | L15: src/api/routes.py | N15: Bắt buộc cho tiêu chí web/app
A16: 9 | B16: T-009 | C16: CERT importer + import summary API | D16: US-07, US-08 | E16: Import subset logon/device/file/http/email/LDAP; status pending/running/completed/failed; summary rows/users/devices/time range | F16: Sprint 3 | G16: P0 | H16: 12 | I16: Mai Ngọc Duy | J16: 18/06/2026 | K16: Đang làm | L16: src/services/ueba_ml | N16: Cần xử lý chunk cho file lớn
A17: 10 | B17: T-010 | C17: Feature builder tích hợp backend | D17: US-11 | E17: Build user/device/day windows, lưu feature_summary/baseline_context và artifact metadata | F17: Sprint 3 | G17: P0 | H17: 10 | I17: Mai Ngọc Duy | J17: 19/06/2026 | K17: Đang làm | L17: POST /api/features/build | N17: Output dùng cho inference
A18: 11 | B18: T-011 | C18: UI shell + login + layout dashboard | D18: US-01, US-15 | E18: React/Next app, auth store, protected routes, sidebar/pages skeleton | F18: Sprint 3 | G18: P0 | H18: 10 | I18: Hoàng Trung Quân | J18: 18/06/2026 | K18: Đang làm | L18: frontend/app | N18: Đủ để demo navigation
A19: 12 | B19: T-012 | C19: Users/Devices/Logs pages + API client | D19: US-03, US-05, US-09 | E19: Bảng users/devices/logs, filter cơ bản, gọi API thật/fallback seed data | F19: Sprint 3 | G19: P0 | H19: 12 | I19: Hoàng Trung Quân | J19: 19/06/2026 | K19: Đang làm | L19: frontend/pages | N19: Phục vụ demo trạng thái hệ thống
B20: Sprint 4: W4 — hoàn thiện anomaly engine và alert loop
A21: 13 | B21: T-013 | C21: Train Isolation Forest + model registry | D21: US-11 | E21: Train reproducible, lưu model_version, training_config, metrics_json, artifact_path | F21: Sprint 4 | G21: P0 | H21: 12 | I21: Mai Ngọc Duy | J21: 23/06/2026 | K21: Chưa bắt đầu | L21: src/services/ueba_ml/pipelines | N21: Core AI của dự án
A22: 14 | B22: T-014 | C22: Batch inference + risk score 0-100 | D22: US-12 | E22: Chuyển anomaly score sang risk_score, severity Low/Medium/High/Critical, top anomalous features | F22: Sprint 4 | G22: P0 | H22: 10 | I22: Mai Ngọc Duy | J22: 24/06/2026 | K22: Chưa bắt đầu | L22: POST /api/models/{version}/infer | N22: Ngưỡng alert risk>=60
A23: 15 | B23: T-015 | C23: Alert service + API filter/status | D23: US-13, US-16 | E23: Tạo alert từ inference, GET/PATCH alerts, filter severity/status/user/device | F23: Sprint 4 | G23: P0 | H23: 10 | I23: Bùi Hoàng Linh | J23: 25/06/2026 | K23: Chưa bắt đầu | L23: src/services/alerts.py | N23: Kết nối ML với dashboard
A24: 16 | B24: T-016 | C24: Dashboard summary endpoints | D24: US-15 | E24: Cards tổng user/device/log/alert, high/critical, top risk users/devices, charts data | F24: Sprint 4 | G24: P0 | H24: 8 | I24: Bùi Hoàng Linh | J24: 26/06/2026 | K24: Chưa bắt đầu | L24: /api/dashboard/* | N24: Giúp UI không tính toán phía client
A25: 17 | B25: T-017 | C25: LLM explanation service + fallback | D25: US-14 | E25: Prompt/fallback từ anomaly_score, top_features, baseline, timeline; không phụ thuộc API key | F25: Sprint 4 | G25: P0 | H25: 10 | I25: Hoàng Trung Quân | J25: 25/06/2026 | K25: Chưa bắt đầu | L25: src/services/llm.py | N25: Bắt buộc có explanation 100% alert
A26: 18 | B26: T-018 | C26: Alerts page + alert detail + timeline UI | D26: US-10, US-14, US-16 | E26: Bảng alerts, màu severity, đổi status, timeline quanh alert, explanation dễ đọc | F26: Sprint 4 | G26: P0 | H26: 12 | I26: Hoàng Trung Quân | J26: 26/06/2026 | K26: Chưa bắt đầu | L26: frontend/alerts | N26: Luồng analyst chính
B27: Sprint 5: W5 — tích hợp end-to-end, QA và deploy staging
A28: 19 | B28: T-019 | C28: E2E flow import → train → infer → alert → explanation | D28: US-07..US-16 | E28: Kịch bản demo chạy từ data đến dashboard; ghi lại steps và expected output | F28: Sprint 5 | G28: P0 | H28: 10 | I28: Cả nhóm | J28: 29/06/2026 | K28: Chưa bắt đầu | L28: scripts/demo_flow.* | N28: Tiêu chí nghiệm thu cốt lõi
A29: 20 | B29: T-020 | C29: Đánh giá model và tuning ngưỡng | D29: US-11, US-12 | E29: Known scenario detection, false positive review, metrics/report trong eval/results | F29: Sprint 5 | G29: P0 | H29: 10 | I29: Mai Ngọc Duy | J29: 01/07/2026 | K29: Chưa bắt đầu | L29: eval/results | N29: Cần số liệu thuyết phục
A30: 21 | B30: T-021 | C30: API tests + integration tests | D30: US-01..US-16 | E30: Test auth, users/devices/logs/alerts, analyze, status update; smoke test health/db | F30: Sprint 5 | G30: P0 | H30: 10 | I30: Bùi Hoàng Linh | J30: 02/07/2026 | K30: Chưa bắt đầu | L30: tests/test_api | N30: Giảm rủi ro demo fail
A31: 22 | B31: T-022 | C31: UI polish + privacy/compliance note | D31: US-14..US-16 | E31: Responsive, loading/error states, privacy notice, empty states, severity visuals | F31: Sprint 5 | G31: P1 | H31: 8 | I31: Hoàng Trung Quân | J31: 02/07/2026 | K31: Chưa bắt đầu | L31: frontend | N31: Tăng chất lượng trải nghiệm
A32: 23 | B32: T-023 | C32: Docker/Deploy staging | D32: US-15, US-16 | E32: Dockerfile/docker-compose, .env.example, deploy backend + frontend, persistent DB/artifacts strategy | F32: Sprint 5 | G32: P0 | H32: 10 | I32: Bùi Hoàng Linh | J32: 03/07/2026 | K32: Chưa bắt đầu | L32: Dockerfile, docker-compose.yml | N32: Cần public URL
B33: Sprint 6: W6 — khóa scope, hoàn thiện bàn giao
A34: 24 | B34: T-024 | C34: Bug bash và sửa lỗi P0/P1 | D34: US-01..US-16 | E34: Chạy checklist demo, sửa bug auth/API/UI/ML/LLM, cập nhật trạng thái bug tracker | F34: Sprint 6 | G34: P0 | H34: 12 | I34: Cả nhóm | J34: 04/07/2026 | K34: Chưa bắt đầu | L34: Theo dõi lỗi | N34: Không thêm scope mới
A35: 25 | B35: T-025 | C35: README + hướng dẫn chạy/deploy/demo | D35: US-01..US-16 | E35: Cách chạy backend/frontend/agent/import/train/infer/deploy; tài khoản demo; privacy note | F35: Sprint 6 | G35: P0 | H35: 8 | I35: Hoàng Trung Quân | J35: 05/07/2026 | K35: Chưa bắt đầu | L35: README.md | N35: Bắt buộc để mentor chạy lại
A36: 26 | B36: T-026 | C36: Chốt production URL + dữ liệu demo | D36: US-15, US-16 | E36: Kiểm tra URL public, seed data/model artifact, demo subset CERT, backup fallback data | F36: Sprint 6 | G36: P0 | H36: 8 | I36: Bùi Hoàng Linh | J36: 05/07/2026 | K36: Chưa bắt đầu | L36: Live URL | N36: Không chấp nhận localhost-only
A37: 27 | B37: T-027 | C37: Slide/kịch bản demo cuối kỳ | D37: US-14..US-16 | E37: Storyline why/who, kiến trúc, demo flow, kết quả model, limitations, next steps | F37: Sprint 6 | G37: P0 | H37: 8 | I37: Cả nhóm | J37: 06/07/2026 | K37: Chưa bắt đầu | L37: presentation/ | N37: Tập demo trước khi nộp

Sheet Đặc tả tính năng
A1: ĐẶC TẢ TÍNH NĂNG / FEATURE SPECIFICATION
A2: Hai đặc tả trọng tâm: Data/ML pipeline và Analyst dashboard + explanation
A4: ĐẶC TẢ #1
A5: Mã User Story liên quan | B5: US-07, US-08, US-11, US-12, US-13
A6: Tên tính năng | B6: CERT r4.2 → Feature Window → Anomaly/Risk → Alert
A7: Người viết | B7: Mai Ngọc Duy
A8: Ngày tạo | B8: 46362
A9: Ngày cập nhật gần nhất | B9: 46362
A10: Trạng thái | B10: Đang làm
A12: 1. ĐỘNG LÝ (MOTIVATION)
A13: Vấn đề cần giải quyết | B13: Log phân mảnh, không có baseline hành vi bình thường, analyst quá tải khi phải tự ghép log thủ công.
A14: Người dùng mục tiêu | B14: Data/ML Engineer, Security Analyst, Admin.
A15: Mục tiêu kỳ vọng | B15: Import/normalize được CERT r4.2, build feature matrix, train iForest, risk score 0-100, tạo alert khi risk>=60.
A16: Phương án thay thế đã xem xét | B16: Rule-based chỉ dùng guardrail/fallback; ML anomaly detection là lõi để bám đề bài.
A17: 2. THIẾT KẾ (DESIGN)
A18: Kiến trúc hệ thống | B18: Raw CERT CSV → normalize endpoint events → aggregate user/device/day → train/infer → risk scoring → alerts DB → dashboard.
A19: Thiết kế API | B19: POST /api/datasets/cert-r42/import, POST /api/features/build, POST /api/models/train, POST /api/models/{version}/infer, GET/PATCH /api/alerts.
A20: Mô hình dữ liệu | B20: event_logs, feature_windows, model_artifacts, alerts; lưu source_file/source_id để truy vết về dòng CSV gốc.
A21: Thiết kế AI/ML | B21: Isolation Forest baseline chính; output anomaly_score, risk_score, severity, top_anomalous_features; report metrics trong eval/results.
A22: Trường hợp đặc biệt và Xử lý lỗi | B22: File CERT lớn/dirty → chunk processing, import error report; thiếu labels → dùng known scenario windows và analyst review.
A23: Bảo mật và Quyền riêng tư | B23: Không hiển thị dữ liệu quá nhạy cảm; chỉ metadata bảo mật; role-based access cho dashboard/log/alert.
A24: 3. KẾ HOẠCH (PLAN)
A25: Các bước thực hiện | B25: W3 importer + features; W4 train/infer/risk/alert; W5 evaluation/tuning; W6 freeze artifact và report.
A26: Công việc con (liên kết Backlog) | B26: T-009, T-010, T-013, T-014, T-015, T-020
A27: Phụ thuộc | B27: Data contract, DB schema, API routes, artifact path.
A28: Timeline dự kiến | B28: 13/06/2026 → 06/07/2026
A29: Kế hoạch kiểm thử | B29: Unit test feature builder; smoke test train/infer; verify alert risk>=60; compare known scenario windows.
A30: Tiêu chí thành công | B30: Inference tạo alert có score, severity, top features và model_version; dashboard đọc được alert.
A31: Rủi ro và Cách giảm thiểu | B31: Dataset lớn/false positives → dùng subset demo, threshold tuning, rule guardrail.
A32: ────────────────────────────────────────────────────────────────────────────────
A35: ĐẶC TẢ #2
A36: Mã User Story liên quan | B36: US-01, US-02, US-03, US-05, US-10, US-14, US-15, US-16
A37: Tên tính năng | B37: Analyst Dashboard + Alert Detail + LLM/Rule-based Explanation
A38: Người viết | B38: Hoàng Trung Quân
A39: Ngày tạo | B39: 13/06/2026
A40: Ngày cập nhật gần nhất | B40: 13/06/2026
A41: Trạng thái | B41: Đang làm
A43: 1. ĐỘNG LÝ (MOTIVATION)
A44: Vấn đề cần giải quyết | B44: Alert thô chỉ có số liệu khiến analyst mất thời gian hiểu vì sao bất thường và phải tự ghép timeline.
A45: Người dùng mục tiêu | B45: Admin, SOC/Security Analyst.
...

Sheet Theo dõi lỗi
A1: THEO DÕI LỖI / RỦI RO (BUG & RISK TRACKING)
A2: Cập nhật liên tục trong 4 tuần còn lại; các mục dưới là rủi ro dự án cần theo dõi trước khi thành bug thật
A4: STT | B4: Mã lỗi/rủi ro | C4: Tiêu đề | D4: Mô tả chi tiết | E4: Cách tái hiện / Dấu hiệu | F4: Mức nghiêm trọng | G4: Ưu tiên | H4: Mã US liên quan | I4: Người xử lý | J4: Ngày phát hiện | K4: Trạng thái | L4: Ngày sửa / Ghi chú
A5: 1 | B5: RISK-001 | C5: CERT r4.2 quá lớn khi import/deploy | D5: http/email/file có thể rất lớn, gây timeout hoặc memory cao | E5: Import full dataset chậm hoặc crash | F5: Cao | G5: P0 | H5: US-07, US-08 | I5: Mai Ngọc Duy | J5: 13/06/2026 | K5: Mở | L5: Mitigation: subset thời gian, chunk processing, summary job
A6: 2 | B6: RISK-002 | C6: LLM API key thiếu hoặc lỗi rate limit | D6: Explanation không được phụ thuộc bắt buộc vào provider | E6: Tắt API key vẫn phải có explanation | F6: Trung bình | G6: P0 | H6: US-14 | I6: Hoàng Trung Quân | J6: 13/06/2026 | K6: Mở | L6: Mitigation: rule-based/template fallback
A7: 3 | B7: RISK-003 | C7: Backend/frontend lệch contract | D7: UI cần dữ liệu dashboard/alert nhưng API schema thay đổi | E7: Frontend lỗi khi gọi API hoặc thiếu field | F7: Cao | G7: P0 | H7: US-15, US-16 | I7: Bùi Hoàng Linh | J7: 13/06/2026 | K7: Mở | L7: Mitigation: docs API example + mock response + daily integration
A8: 4 | B8: RISK-004 | C8: Model false positive cao | D8: Anomaly detection không có ground truth đầy đủ, dễ khó giải thích | E8: High alert quá nhiều hoặc không trúng known scenarios | F8: Trung bình | G8: P1 | H8: US-11, US-12 | I8: Mai Ngọc Duy | J8: 13/06/2026 | K8: Mở | L8: Mitigation: threshold tuning, top features, rule guardrail
A9: 5 | B9: RISK-005 | C9: Deploy không có persistence | D9: SQLite/artifacts mất sau restart nếu deploy sai | E9: Reload app mất alert/model/user seed | F9: Cao | G9: P0 | H9: US-15, US-16 | I9: Bùi Hoàng Linh | J9: 13/06/2026 | K9: Mở | L9: Mitigation: persistent disk/Postgres/seed backup
A10: 6 | B10: RISK-006 | C10: Không đủ thời gian hoàn thiện UI/UX | D10: Dashboard nhiều trang, dễ thiếu trạng thái empty/loading/error | E10: Demo trải nghiệm rời rạc | F10: Trung bình | G10: P1 | H10: US-15, US-16 | I10: Hoàng Trung Quân | J10: 13/06/2026 | K10: Mở | L10: Mitigation: ưu tiên flow chính alerts, giảm scope phụ
A12: THANG MỨC NGHIÊM TRỌNG
B13: Nghiêm trọng | C13: Ứng dụng sập hoặc mất dữ liệu — Không thể sử dụng được
B14: Cao | C14: Tính năng chính không hoạt động đúng, ảnh hưởng demo hoặc nhiều người dùng
B15: Trung bình | C15: Tính năng phụ bị lỗi, trải nghiệm không tốt nhưng vẫn dùng được
B16: Thấp | C16: Lỗi nhỏ, liên quan giao diện, không ảnh hưởng chức năng

Sheet Tài liệu quan trọng
A1: DANH SÁCH TÀI LIỆU QUAN TRỌNG
A2: Tập hợp link tới mọi tài liệu dự án — Cập nhật ngay khi có tài liệu mới
A4: STT | B4: Phân loại | C4: Tên tài liệu | D4: Mô tả ngắn | E4: Đường link | F4: Người tạo | G4: Ngày tạo | H4: Cập nhật lần cuối
B5: Quy trình và Hướng dẫn
A6: 1 | C6: Product Brief / Why-Who | D6: Bối cảnh, pain points, đối tượng sử dụng, scope MVP, privacy note | E6: docs/BRIEF.md | F6: Hoàng Trung Quân | G6: W1 | H6: Đã có
A7: 2 | C7: PRD / Product Requirements | D7: User stories, acceptance criteria, demo flow, API/pages, tiêu chí hoàn thành | E7: docs/PRD.md | F7: Hoàng Trung Quân | G7: W1 | H7: Đã có
A8: 3 | C8: Lộ trình 6 tuần chi tiết | D8: Kế hoạch từ W1 đến W6, trong đó W3-W6 là 4 tuần còn lại | F8: Cả nhóm | G8: W2 | H8: Đang cập nhật
B9: Thiết kế và Đặc tả
A10: 4 | C10: Sơ đồ kiến trúc hệ thống | D10: Luồng Endpoint/CERT logs → ML pipeline → FastAPI → Dashboard | E10: docs/architecture_diagram.md | F10: Bùi Hoàng Linh | G10: W2 | H10: Đã có
A11: 5 | C11: Tài liệu kiến trúc | D11: Module boundaries: src/api, src/models, src/services, src/agents, artifacts, data | E11: docs/ARCHITECTURE.md | F11: Bùi Hoàng Linh | G11: W2 | H11: Đã có
A12: 6 | C12: Data Contract | D12: Schema normalized endpoint event, CERT mapping, feature artifacts | E12: docs/DATA_CONTRACT.md | F12: Mai Ngọc Duy | G12: W2 | H12: Đã có
A13: 7 | C13: Repo Structure Standard | D13: Quy tắc cấu trúc repo theo AI20K starter-code-template | E13: docs/REPO_STRUCTURE_STANDARD.md | F13: Bùi Hoàng Linh | G13: W2 | H13: Đã có
A14: 8 | C14: Tài liệu API / Swagger / Postman | D14: Danh sách endpoint auth, users, devices, logs, dataset, models, alerts, dashboard | F14: Bùi Hoàng Linh | G14: W3 | H14: Cần viết
B15: Báo cáo và Biên bản họp
A16: 9 | C16: Biên bản họp nội bộ | D16: Quyết định phân công, blockers, mốc tích hợp từng tuần | F16: Cả nhóm | G16: W3-W6 | H16: Cần cập nhật
A17: 10 | C17: WORKLOG.md | D17: Nhật ký công việc theo ngày/tuần, PR liên quan, trạng thái hoàn thành | E17: WORKLOG.md | F17: Hoàng Trung Quân | G17: W3-W6 | H17: Cần viết
A18: 11 | C18: JOURNAL.md | D18: Ghi chú quá trình phát triển, quyết định kỹ thuật, bài học | E18: JOURNAL.md | F18: Cả nhóm | G18: W3-W6 | H18: Cần viết
A19: 12 | C19: Báo cáo đánh giá model | D19: Metrics, known scenario detection, threshold tuning, false positive review | E19: eval/results/ | F19: Mai Ngọc Duy | G19: W5 | H19: Cần viết
B20: Triển khai và Kiểm thử
A21: 13 | C21: README.md | D21: Hướng dẫn chạy backend/frontend/agent/import/train/infer/deploy và tài khoản demo | E21: README.md | F21: Hoàng Trung Quân | G21: W6 | H21: Cần viết
A22: 14 | C22: Hướng dẫn triển khai | D22: Docker/.env/deploy backend + frontend + DB/artifacts; URL public | E22: docs/DEPLOYMENT.md | F22: Bùi Hoàng Linh | G22: W5-W6 | H22: Cần viết
A23: 15 | C23: Tài liệu kiểm thử | D23: Test cases auth/API/UI/ML/alert/status update; kết quả bug bash | E23: tests/ / eval/results/ | F23: Bùi Hoàng Linh | G23: W5-W6 | H23: Cần viết
A24: 16 | C24: Kịch bản demo | D24: Flow đăng nhập → import → train → infer → alert detail → đổi status | E24: presentation/demo_script.md | F24: Hoàng Trung Quân | G24: W6 | H24: Cần viết
B25: Bàn giao cuối kỳ
A26: 17 | C26: Slide thuyết trình cuối kỳ | D26: Why/Who, kiến trúc, demo flow, kết quả model, privacy, limitations, next steps | E26: presentation/ | F26: Cả nhóm | G26: W6 | H26: Cần viết
A27: 18 | C27: Live URL sản phẩm | D27: URL dashboard/API public; không chỉ localhost | E27: [Dán live URL W5-W6] | F27: Bùi Hoàng Linh | G27: W5-W6 | H27: Chưa có
A28: 19 | C28: GitHub repository | D28: Source code, issue/PR, README, release/tag demo | E28: https://github.com/AI20K-Build-Cohort-2/C2-App-047 | F28: Cả nhóm | G28: W1-W6 | H28: Đang cập nhật
A29: 20 | C29: Video/ảnh minh chứng demo | D29: Ảnh chụp dashboard, alert detail, model metrics, deployment | E29: [Dán link vào đây] | F29: Cả nhóm | G29: W6 | H29: Cần bổ sung

Sheet Hướng dẫn sử dụng
A1: HƯỚNG DẪN SỬ DỤNG TEMPLATE
A2: Đọc kỹ trước khi bắt đầu điền — Tránh sai sót và tận dụng tối đa các tính năng
A4: A. TỔNG QUAN VỀ TEMPLATE
A5: Mục đích | B5: Template này là hồ sơ quản lý dự án duy nhất của nhóm. Mọi thông tin về tiến độ, công việc, lỗi, và tài liệu đều được ghi nhận tại đây. Trưởng nhóm chịu trách nhiệm cập nhật liên tục.
A6: Nguyên tắc cốt lõi | B6: • Chỉ có 1 bản duy nhất — không tách file, không copy • Cập nhật ít nhất 1 lần/ngày trong giờ làm việc • Mọi thành viên đều đọc được, chỉ Trưởng nhóm và người được ủy quyền mới sửa
A7: Đối tượng sử dụng | B7: • Trưởng nhóm: Quản lý, phân việc, báo cáo • Thành viên: Xem công việc, cập nhật trạng thái • Mentor: Theo dõi tiến độ, đánh giá • Đối tác (Stakeholder): XemDemo, phản hồi
A9: B. HƯỚNG DẪN TỪNG SHEET
A10: 1. Tổng hợp | B10: • Điền thông tin dự án ở phần đầu (tên, nhóm, ngày, trưởng nhóm) • Chọn "Tình hình hiện tại" ở ô B3: Đúng tiến độ / Có rủi ro / Bị kẹt • Các chỉ số ở dưới sẽ tự động đếm từ các sheet khác (không cần điền tay) • Cập nhật trạng thái Sprint khi bắt đầu/kết thúc mỗi Sprint
A11: 2. Đường link quan trọng | B11: • Dán mọi link liên quan vào đúng phân loại • Khi thêm link mới, điền ngay "Người quản lý" để biết ai phụ trách • Xóa placeholder [Dán link vào đây] khi đã điền link thật
A12: 3. Thành viên nhóm | B12: • Điền đủ 4 thành viên với vai trò chính xác • Tham khảo bảng phân vai bên dưới để hiểu trách nhiệm mỗi vai • Cập nhật nếu có thay đổi nhân sự
A13: 4. Danh sách User Story | B13: • Viết theo cấu trúc: "Với vai trò [X], tôi muốn [Y], để đạt được [Z]" • Chọn Mức ưu tiên từ dropdown: Bắt buộc / Nên có / Có thì tốt / Không làm • Mã US (US-001, US-002...) dùng để liên kết với Backlog và Đặc tả
A14: 5. Lộ trình | B14: • 8 mốc quan trọng đã được tạo sẵn theo quy trình 6 tuần • Cập nhật ngày cụ thể khi bắt đầu dự án • Chuyển trạng thái sang "Hoàn thành" ngay khi đạt được mốc
A15: 6. Backlog | B15: • Đây là sheet quan trọng nhất — Phân công và theo dõi mọi công việc • Mỗi việc phải có: Mã US liên quan, Người phụ trách, Hạn chót, Trạng thái • Ưu tiên P0 = phải làm ngay, P3 = làm nếu còn thời gian • Trạng thái sẽ tự đổi màu: Xanh = Hoàn thành, Vàng = Đang làm, Đỏ = Bị kẹt
A16: 7. Đặc tả tính năng | B16: • Viết đặc tả theo 3 phần: Động lực → Thiết kế → Kế hoạch • Mỗi tính năng quan trọng cần có 1 đặc tả riêng • Liên kết mã US và mã Task từ Backlog để dễ tra cứu
A17: 8. Theo dõi lỗi | B17: • Báo lỗi ngay khi phát hiện — không đợi • Điền đủ "Cách tái hiện" để người sửa hiểu rõ vấn đề • Chọn Mức nghiêm trọng phù hợp (xem thang đo ở cuối sheet) • Màu tự động hiện: Đỏ = Nghiêm trọng, Vàng = Trung bình, Xanh = Thấp
A18: 9. Tài liệu quan trọng | B18: • Lưu link mọi tài liệu dự án theo đúng phân loại • Cập nhật "Cập nhật lần cuối" mỗi khi sửa tài liệu • Đây là nơi duy nhất để tìm tài liệu — không để link rải rác ở Discord/Email
A20: C. MẸO SỬ DỤNG HIỆU QUẢ
A21: Dropdown tự động | B21: Nhiều cột đã có sẵn danh sách chọn (Priority, Status, Severity). Nhấn vào ô và chọn từ dropdown — không gõ tay để tránh sai chính tả.
A22: Màu sắc tự động | B22: Trạng thái sẽ tự đổi màu theo giá trị: • Xanh lá = Hoàn thành / Thấp • Vàng = Đang làm / Trung bình • Đỏ = Bị kẹt / Nghiêm trọng / P0
A23: Công thức tự động | B23: Một số ô ở sheet Tổng hợp sẽ tự động đếm số lượng từ các sheet khác. KHÔNG sửa các ô có công thức (bắt đầu bằng dấu =).
A24: Liên kết giữa các sheet | B24: Mã User Story (US-001) xuất hiện ở 4 sheet: Danh sách US, Backlog, Đặc tả, và Theo dõi lỗi. Dùng mã này để tra cứu chéo.
A25: Quy trình hàng ngày | B25: 1. Sáng: Mở file, kiểm tra công việc hôm nay trong Backlog 2. Trong ngày: Cập nhật trạng thái công việc khi thay đổi 3. Chiều: Báo cáo standup dựa trên thông tin trong file 4. Tối: Trưởng nhóm kiểm tra và tổng hợp
A27: D. LƯU Ý QUAN TRỌNG
A28: Không xóa dòng có sẵn | B28: Các dòng đã có mã (US-001, T-001, BUG-001) được giữ sẵn để điền. Chỉ cần điền nội dung, không cần thêm dòng mới trừ khi hết chỗ.
A29: Luôn lưu (Ctrl+S) | B29: Nếu dùng Google Sheets, dữ liệu tự lưu. Nếu dùng Excel, nhớ lưu thường xuyên.
A30: Bảo mật | B30: Không chia sẻ file công khai. Chỉ chia sẻ cho thành viên nhóm và mentor.

Sheet Kế hoạch 4 tuần
A1: KẾ HOẠCH 4 TUẦN CÒN LẠI — AI20K-107 UEBA
A2: Phác thảo trước khi điền backlog: mục tiêu là MVP web/app hoàn chỉnh, có auth/RBAC, dashboard, ML anomaly detection, LLM/fallback explanation và deploy URL.
A4: Tuần | B4: Ngày | C4: Mục tiêu chính | D4: Mai Ngọc Duy — Data/ML | E4: Bùi Hoàng Linh — Backend/DevOps | F4: Hoàng Trung Quân — Frontend/LLM/Product | G4: Deliverable kiểm chứng | H4: Mốc | I4: Rủi ro chính | J4: Cách giảm rủi ro | K4: Done khi
A5: W3 | B5: 13/06–19/06 | C5: Dựng MVP nền chạy được | D5: CERT importer, feature builder, data quality report | E5: DB schema, auth/RBAC, APIs users/devices/logs | F5: UI shell, login, users/devices/logs pages | G5: Đăng nhập được, import subset tạo event/feature, UI gọi API | H5: M3 | I5: Dataset lớn, API/UI lệch contract | J5: Chốt schema sớm, dùng subset demo, daily integration | K5: Demo local E2E phần nền
A6: W4 | B6: 20/06–26/06 | C6: Hoàn thiện anomaly engine và alert loop | D6: Train iForest, inference, risk 0-100, top features | E6: Alert service, status API, dashboard summary endpoints | F6: LLM/fallback explanation, alerts page/detail/timeline UI | G6: Chạy inference tạo alert risk>=60 có explanation | H6: M4 | I6: Model nhiều false positive, thiếu API key LLM | J6: Tuning threshold, fallback rule-based | K6: Alert detail hiển thị đủ score/features/timeline
A7: W5 | B7: 27/06–03/07 | C7: Tích hợp end-to-end + QA + deploy staging | D7: Evaluate known scenarios, metrics/report, demo subset | E7: Tests, Docker, deploy backend/staging DB | F7: UI polish, privacy note, demo walkthrough | G7: Flow import→train→infer→alert→explanation chạy từ UI | H7: M5 | I7: Deploy lỗi, dữ liệu/artifact không persistent | J7: Docker, .env.example, backup seed/artifact | K7: Staging URL truy cập được
A8: W6 | B8: 04/07–06/07 | C8: Khóa scope, fix bug, bàn giao final | D8: Cố định model artifact, metrics cuối, hỗ trợ bug bash | E8: Chốt public URL, smoke test, deploy fallback | F8: README, slide/demo script, kiểm tra UX cuối | G8: Public URL + README + final demo + presentation | H8: M6 | I8: Demo fail do live URL/API/key | J8: Checklist trước demo, fallback offline/seed data | K8: Mentor có thể mở URL và xem demo loop
A10: Nguyên tắc phân công | B10: Owner rõ ràng; mỗi task có backup; ưu tiên P0 trước; không thêm scope mới sau W5; mọi alert phải có explanation fallback.
A12: Checklist MVP bắt buộc | B12: Web/app deployed online | C12: Login & phân quyền | D12: Dashboard users/devices/logs/alerts | E12: CERT import + normalized events | F12: Feature engineering + iForest | G12: Risk score 0-100 + severity | H12: Alert detail + timeline | I12: LLM/fallback explanation | J12: README + demo script | K12: Privacy note
